{
 "cells": [
  {
   "cell_type": "code",
   "execution_count": 3,
   "metadata": {},
   "outputs": [],
   "source": [
    "import tensorflow as tf"
   ]
  },
  {
   "cell_type": "code",
   "execution_count": 6,
   "metadata": {},
   "outputs": [
    {
     "name": "stderr",
     "output_type": "stream",
     "text": [
      "ERROR:root:Internal Python error in the inspect module.\n",
      "Below is the traceback from this internal error.\n",
      "\n"
     ]
    },
    {
     "name": "stdout",
     "output_type": "stream",
     "text": [
      "Traceback (most recent call last):\n",
      "  File \"C:\\Users\\user\\Anaconda3\\lib\\site-packages\\IPython\\core\\interactiveshell.py\", line 3325, in run_code\n",
      "    exec(code_obj, self.user_global_ns, self.user_ns)\n",
      "  File \"<ipython-input-6-65f07e81e169>\", line 1, in <module>\n",
      "    print(tf.__version__)\n",
      "AttributeError: module 'tensorflow' has no attribute '__version__'\n",
      "\n",
      "During handling of the above exception, another exception occurred:\n",
      "\n",
      "Traceback (most recent call last):\n",
      "  File \"C:\\Users\\user\\Anaconda3\\lib\\site-packages\\IPython\\core\\interactiveshell.py\", line 2039, in showtraceback\n",
      "    stb = value._render_traceback_()\n",
      "AttributeError: 'AttributeError' object has no attribute '_render_traceback_'\n",
      "\n",
      "During handling of the above exception, another exception occurred:\n",
      "\n",
      "Traceback (most recent call last):\n",
      "  File \"C:\\Users\\user\\Anaconda3\\lib\\site-packages\\IPython\\core\\ultratb.py\", line 1101, in get_records\n",
      "    return _fixed_getinnerframes(etb, number_of_lines_of_context, tb_offset)\n",
      "  File \"C:\\Users\\user\\Anaconda3\\lib\\site-packages\\IPython\\core\\ultratb.py\", line 319, in wrapped\n",
      "    return f(*args, **kwargs)\n",
      "  File \"C:\\Users\\user\\Anaconda3\\lib\\site-packages\\IPython\\core\\ultratb.py\", line 353, in _fixed_getinnerframes\n",
      "    records = fix_frame_records_filenames(inspect.getinnerframes(etb, context))\n",
      "  File \"C:\\Users\\user\\Anaconda3\\lib\\inspect.py\", line 1502, in getinnerframes\n",
      "    frameinfo = (tb.tb_frame,) + getframeinfo(tb, context)\n",
      "  File \"C:\\Users\\user\\Anaconda3\\lib\\inspect.py\", line 1460, in getframeinfo\n",
      "    filename = getsourcefile(frame) or getfile(frame)\n",
      "  File \"C:\\Users\\user\\Anaconda3\\lib\\inspect.py\", line 696, in getsourcefile\n",
      "    if getattr(getmodule(object, filename), '__loader__', None) is not None:\n",
      "  File \"C:\\Users\\user\\Anaconda3\\lib\\inspect.py\", line 733, in getmodule\n",
      "    if ismodule(module) and hasattr(module, '__file__'):\n",
      "  File \"C:\\Users\\user\\Anaconda3\\lib\\site-packages\\tensorflow\\__init__.py\", line 50, in __getattr__\n",
      "    module = self._load()\n",
      "  File \"C:\\Users\\user\\Anaconda3\\lib\\site-packages\\tensorflow\\__init__.py\", line 44, in _load\n",
      "    module = _importlib.import_module(self.__name__)\n",
      "  File \"C:\\Users\\user\\Anaconda3\\lib\\importlib\\__init__.py\", line 127, in import_module\n",
      "    return _bootstrap._gcd_import(name[level:], package, level)\n",
      "  File \"<frozen importlib._bootstrap>\", line 1006, in _gcd_import\n",
      "  File \"<frozen importlib._bootstrap>\", line 983, in _find_and_load\n",
      "  File \"<frozen importlib._bootstrap>\", line 953, in _find_and_load_unlocked\n",
      "  File \"<frozen importlib._bootstrap>\", line 219, in _call_with_frames_removed\n",
      "  File \"<frozen importlib._bootstrap>\", line 1006, in _gcd_import\n",
      "  File \"<frozen importlib._bootstrap>\", line 983, in _find_and_load\n",
      "  File \"<frozen importlib._bootstrap>\", line 967, in _find_and_load_unlocked\n",
      "  File \"<frozen importlib._bootstrap>\", line 677, in _load_unlocked\n",
      "  File \"<frozen importlib._bootstrap_external>\", line 728, in exec_module\n",
      "  File \"<frozen importlib._bootstrap>\", line 219, in _call_with_frames_removed\n",
      "  File \"C:\\Users\\user\\Anaconda3\\lib\\site-packages\\tensorflow_core\\__init__.py\", line 46, in <module>\n",
      "    from . _api.v2 import compat\n",
      "  File \"C:\\Users\\user\\Anaconda3\\lib\\site-packages\\tensorflow_core\\_api\\v2\\compat\\__init__.py\", line 39, in <module>\n",
      "    from . import v1\n",
      "  File \"C:\\Users\\user\\Anaconda3\\lib\\site-packages\\tensorflow_core\\_api\\v2\\compat\\v1\\__init__.py\", line 32, in <module>\n",
      "    from . import compat\n",
      "  File \"C:\\Users\\user\\Anaconda3\\lib\\site-packages\\tensorflow_core\\_api\\v2\\compat\\v1\\compat\\__init__.py\", line 39, in <module>\n",
      "    from . import v1\n",
      "  File \"C:\\Users\\user\\Anaconda3\\lib\\site-packages\\tensorflow_core\\_api\\v2\\compat\\v1\\compat\\v1\\__init__.py\", line 29, in <module>\n",
      "    from tensorflow._api.v2.compat.v1 import app\n",
      "  File \"C:\\Users\\user\\Anaconda3\\lib\\site-packages\\tensorflow_core\\_api\\v2\\compat\\__init__.py\", line 39, in <module>\n",
      "    from . import v1\n",
      "  File \"C:\\Users\\user\\Anaconda3\\lib\\site-packages\\tensorflow_core\\_api\\v2\\compat\\v1\\__init__.py\", line 32, in <module>\n",
      "    from . import compat\n",
      "  File \"C:\\Users\\user\\Anaconda3\\lib\\site-packages\\tensorflow_core\\_api\\v2\\compat\\v1\\compat\\__init__.py\", line 39, in <module>\n",
      "    from . import v1\n",
      "  File \"C:\\Users\\user\\Anaconda3\\lib\\site-packages\\tensorflow_core\\_api\\v2\\compat\\v1\\compat\\v1\\__init__.py\", line 74, in <module>\n",
      "    from tensorflow._api.v2.compat.v1 import summary\n",
      "  File \"C:\\Users\\user\\Anaconda3\\lib\\site-packages\\tensorflow_core\\_api\\v2\\compat\\v1\\summary\\__init__.py\", line 14, in <module>\n",
      "    from tensorflow.python import Event\n",
      "ImportError: cannot import name 'Event' from 'tensorflow_core.python' (unknown location)\n"
     ]
    },
    {
     "ename": "AttributeError",
     "evalue": "module 'tensorflow' has no attribute '__version__'",
     "output_type": "error",
     "traceback": [
      "\u001b[1;31m---------------------------------------------------------------------------\u001b[0m"
     ]
    }
   ],
   "source": [
    "print(tf.__version__)"
   ]
  },
  {
   "cell_type": "code",
   "execution_count": null,
   "metadata": {},
   "outputs": [],
   "source": []
  }
 ],
 "metadata": {
  "kernelspec": {
   "display_name": "Python 3",
   "language": "python",
   "name": "python3"
  },
  "language_info": {
   "codemirror_mode": {
    "name": "ipython",
    "version": 3
   },
   "file_extension": ".py",
   "mimetype": "text/x-python",
   "name": "python",
   "nbconvert_exporter": "python",
   "pygments_lexer": "ipython3",
   "version": "3.7.3"
  }
 },
 "nbformat": 4,
 "nbformat_minor": 2
}
